Workbook
Name Slicer_Candidate_Source: #N/A
Name Slicer_Department: #N/A
Name Slicer_Hire_Status: #N/A
Name Slicer_Offer_Status: #N/A

Sheet Recruitment
A1: Position ID | B1: Department | C1: Level/Band | D1: Designation Vacancy | E1: Position Requisition Date | F1: Vacancy approval date | G1: Job advert open date | H1: Job advert closing date | I1: Shortlisted Status | J1: Interview date | K1: Hire Status | L1: Date job offer | M1: Offer Status | N1: Reporting date | O1: Date of induction/onboarding | P1: Hired | Q1: Date e-file opened | R1: Date of inclusion to benefits | S1: Date of File Closure | T1: Candidate ID | U1: Candidate Name | V1: Candidate Source | W1: Probation (Months) | X1: Application Date | Y1: Time between Application and Interview | Z1: Time to Hire | AA1: Time to Publish Advert | AB1: Open Days | AC1: Time between Onboarding and File Opening | AD1: Time between Interview and Candidate Reporting | AE1: Time to Approve Requisition | AF1: Time to Close Employee File | AG1: Time of Inclusion to Benefits | AH1: End of Probation Date
A2: 524 | B2: Risk Management | C2: Associate | D2: Analyst | E2: 44605 | G2: 44611 | H2: 44616 | I2: Yes | J2: 44617 | K2: Decline | L2: 44622 | M2: Declined | N2: 44619 | P2: 0 | T2: C1001 | U2: Candidate_1 | V2: Linkedin | W2: 3 | X2: 44603 | Y2: 14 | Z2: 5 | AA2: 6 | AB2: 5 | AD2: 2 | AH2: =EDATE(Sheet1__2[[#This Row],[Reporting date ]], Sheet1__2[[#This Row],[Probation (Months)]]) -> 44708
A3: 522 | B3: Risk Management | C3: Associate | D3: Analyst | E3: 44609 | F3: 44610 | G3: 44611 | H3: 44620 | I3: Yes | J3: 44613 | K3: Decline | L3: 44618 | M3: Declined | N3: 44614 | P3: 0 | T3: C1002 | U3: Candidate_2 | V3: Job Board | W3: 6 | X3: 44683 | Y3: -70 | Z3: 5 | AA3: 2 | AB3: 9 | AD3: 1 | AE3: 1 | AH3: =EDATE(Sheet1__2[[#This Row],[Reporting date ]], Sheet1__2[[#This Row],[Probation (Months)]]) -> 44795
A4: 401 | B4: Risk Management | C4: Executive | D4: Director | E4: 44613 | F4: 44616 | G4: 44622 | H4: 44645 | I4: Yes | J4: 44626 | K4: Decline | L4: 44630 | M4: Declined | N4: 44627 | P4: 0 | T4: C1004 | U4: Candidate_4 | V4: Referral | W4: 6 | X4: 44615 | Y4: 11 | Z4: 4 | AA4: 9 | AB4: 23 | AD4: 1 | AE4: 3 | AH4: =EDATE(Sheet1__2[[#This Row],[Reporting date ]], Sheet1__2[[#This Row],[Probation (Months)]]) -> 44811
A5: 408 | B5: Risk Management | C5: Junior | D5: Analyst | E5: 44617 | F5: 44620 | G5: 44622 | H5: 44634 | I5: Yes | J5: 44627 | K5: Decline | L5: 44634 | M5: Declined | N5: 44631 | P5: 0 | T5: C1007 | U5: Candidate_7 | V5: Job Board | W5: 3 | X5: 44609 | Y5: 18 | Z5: 7 | AA5: 5 | AB5: 12 | AD5: 4 | AE5: 3 | AH5: =EDATE(Sheet1__2[[#This Row],[Reporting date ]], Sheet1__2[[#This Row],[Probation (Months)]]) -> 44723
A6: 405 | B6: Risk Management | C6: Executive | D6: Director | E6: 44617 | G6: 44622 | H6: 44650 | I6: Yes | J6: 44625 | K6: Accepted | L6: 44627 | M6: Accepted | N6: 44626 | O6: 44628 | P6: 1 | Q6: 44631 | R6: 44636 | S6: 44648 | T6: C1009 | U6: Candidate_9 | V6: Linkedin | W6: 6 | X6: 44607 | Y6: 18 | Z6: 2 | AA6: 5 | AB6: 28 | AC6: 3 | AD6: 1 | AF6: 17 | AG6: 10 | AH6: =EDATE(Sheet1__2[[#This Row],[Reporting date ]], Sheet1__2[[#This Row],[Probation (Months)]]) -> 44810
A7: 410 | B7: Risk Management | C7: Associate | D7: Supervisor | E7: 44618 | F7: 44620 | G7: 44622 | H7: 44651 | I7: Yes | J7: 44624 | K7: Decline | L7: 44628 | M7: Declined | N7: 44625 | P7: 0 | T7: C1010 | U7: Candidate_10 | V7: Job Board | W7: 6 | X7: 44605 | Y7: 19 | Z7: 4 | AA7: 4 | AB7: 29 | AD7: 1 | AE7: 2 | AH7: =EDATE(Sheet1__2[[#This Row],[Reporting date ]], Sheet1__2[[#This Row],[Probation (Months)]]) -> 44809
A8: 211 | B8: Risk Management | C8: Junior | D8: Analyst | E8: 44657 | F8: 44661 | G8: 44666 | H8: 44682 | I8: Yes | J8: 44682 | K8: Accepted | L8: 44688 | M8: Accepted | N8: 44685 | O8: 44692 | P8: 1 | Q8: 44694 | R8: 44698 | S8: 44714 | T8: C1011 | U8: Candidate_11 | V8: Linkedin | W8: 6 | X8: 44675 | Y8: 7 | Z8: 6 | AA8: 9 | AB8: 16 | AC8: 2 | AD8: 3 | AE8: 4 | AF8: 20 | AG8: 13 | AH8: =EDATE(Sheet1__2[[#This Row],[Reporting date ]], Sheet1__2[[#This Row],[Probation (Months)]]) -> 44869
A9: 219 | B9: Risk Management | C9: Associate | D9: Supervisor | E9: 44657 | F9: 44660 | G9: 44666 | H9: 44684 | I9: Yes | J9: 44675 | K9: Decline | L9: 44681 | M9: Declined | N9: 44679 | P9: 0 | T9: C1012 | U9: Candidate_12 | V9: Job Board | W9: 3 | X9: 44669 | Y9: 6 | Z9: 6 | AA9: 9 | AB9: 18 | AD9: 4 | AE9: 3 | AH9: =EDATE(Sheet1__2[[#This Row],[Reporting date ]], Sheet1__2[[#This Row],[Probation (Months)]]) -> 44770
A10: 338 | B10: Risk Management | C10: Associate | D10: Supervisor | E10: 44720 | F10: 44722 | H10: 44739 | I10: Yes | J10: 44729 | K10: Decline | L10: 44732 | M10: Declined | N10: 44731 | P10: 0 | T10: C1017 | U10: Candidate_17 | V10: Job Board | W10: 3 | X10: 44687 | Y10: 42 | Z10: 3 | AD10: 2 | AE10: 2 | AH10: =EDATE(Sheet1__2[[#This Row],[Reporting date ]], Sheet1__2[[#This Row],[Probation (Months)]]) -> 44823
A11: 335 | B11: Risk Management | C11: Executive | D11: Director | E11: 44723 | F11: 44724 | G11: 44725 | H11: 44748 | I11: Yes | J11: 44729 | K11: Decline | L11: 44734 | M11: Declined | N11: 44731 | P11: 0 | T11: C1018 | U11: Candidate_18 | V11: Referral | W11: 3 | X11: 44710 | Y11: 19 | Z11: 5 | AA11: 2 | AB11: 23 | AD11: 2 | AE11: 1 | AH11: =EDATE(Sheet1__2[[#This Row],[Reporting date ]], Sheet1__2[[#This Row],[Probation (Months)]]) -> 44823
A12: 33 | B12: Risk Management | C12: Executive | D12: Head of Department | E12: 44773 | F12: 44776 | G12: 44778 | H12: 44799 | I12: Yes | J12: 44788 | K12: Decline | L12: 44795 | M12: Declined | N12: 44791 | P12: 0 | T12: C1020 | U12: Candidate_20 | V12: Referral | W12: 3 | X12: 44778 | Y12: 10 | Z12: 7 | AA12: 5 | AB12: 21 | AD12: 3 | AE12: 3 | AH12: =EDATE(Sheet1__2[[#This Row],[Reporting date ]], Sheet1__2[[#This Row],[Probation (Months)]]) -> 44883
A13: 34 | B13: Risk Management | C13: Executive | D13: Head of Department | E13: 44774 | F13: 44777 | G13: 44778 | H13: 44786 | I13: Yes | J13: 44792 | K13: Decline | L13: 44797 | M13: Declined | N13: 44793 | P13: 0 | T13: C1021 | U13: Candidate_21 | V13: Referral | W13: 6 | X13: 44784 | Y13: 8 | Z13: 5 | AA13: 4 | AB13: 8 | AD13: 1 | AE13: 3 | AH13: =EDATE(Sheet1__2[[#This Row],[Reporting date ]], Sheet1__2[[#This Row],[Probation (Months)]]) -> 44977
A14: 32 | B14: Risk Management | C14: Executive | D14: Head of Department | E14: 44774 | F14: 44777 | G14: 44778 | H14: 44786 | I14: Yes | J14: 44787 | K14: Accepted | L14: 44795 | M14: Accepted | N14: 44791 | O14: 44800 | P14: 1 | Q14: 44803 | R14: 44807 | S14: 44825 | T14: C1022 | U14: Candidate_22 | V14: Referral | W14: 3 | X14: 44775 | Y14: 12 | Z14: 8 | AA14: 4 | AB14: 8 | AC14: 3 | AD14: 4 | AE14: 3 | AF14: 22 | AG14: 16 | AH14: =EDATE(Sheet1__2[[#This Row],[Reporting date ]], Sheet1__2[[#This Row],[Probation (Months)]]) -> 44883
A15: 518 | B15: Risk Management | C15: Associate | D15: Analyst | E15: 44846 | F15: 44850 | G15: 44856 | H15: 44875 | I15: Yes | J15: 44871 | K15: Decline | L15: 44875 | M15: Declined | N15: 44874 | P15: 0 | T15: C1024 | U15: Candidate_24 | V15: Referral | W15: 3 | X15: 44852 | Y15: 19 | Z15: 4 | AA15: 10 | AB15: 19 | AD15: 3 | AE15: 4 | AH15: =EDATE(Sheet1__2[[#This Row],[Reporting date ]], Sheet1__2[[#This Row],[Probation (Months)]]) -> 44966
A16: 519 | B16: Risk Management | C16: Junior | D16: Analyst | E16: 44850 | F16: 44854 | G16: 44856 | H16: 44870 | I16: Yes | J16: 44866 | K16: Decline | L16: 44871 | M16: Declined | N16: 44870 | P16: 0 | T16: C1026 | U16: Candidate_26 | V16: Linkedin | W16: 6 | X16: 44858 | Y16: 8 | Z16: 5 | AA16: 6 | AB16: 14 | AD16: 4 | AE16: 4 | AH16: =EDATE(Sheet1__2[[#This Row],[Reporting date ]], Sheet1__2[[#This Row],[Probation (Months)]]) -> 45051
A17: 512 | B17: Risk Management | C17: Junior | D17: Analyst | E17: 44851 | F17: 44854 | G17: 44856 | H17: 44876 | I17: Yes | J17: 44869 | K17: Decline | L17: 44874 | M17: Declined | N17: 44870 | P17: 0 | T17: C1027 | U17: Candidate_27 | V17: Referral | W17: 3 | X17: 44863 | Y17: 6 | Z17: 5 | AA17: 5 | AB17: 20 | AD17: 1 | AE17: 3 | AH17: =EDATE(Sheet1__2[[#This Row],[Reporting date ]], Sheet1__2[[#This Row],[Probation (Months)]]) -> 44962
A18: 515 | B18: Risk Management | C18: Associate | D18: Analyst | E18: 44852 | F18: 44854 | G18: 44856 | H18: 44876 | I18: Yes | J18: 44871 | K18: Accepted | L18: 44877 | M18: Accepted | N18: 44874 | O18: 44875 | P18: 1 | Q18: 44878 | R18: 44883 | S18: 44901 | T18: C1028 | U18: Candidate_28 | V18: Referral | W18: 3 | X18: 44856 | Y18: 15 | Z18: 6 | AA18: 4 | AB18: 20 | AC18: 3 | AD18: 3 | AE18: 2 | AF18: 23 | AG18: 9 | AH18: =EDATE(Sheet1__2[[#This Row],[Reporting date ]], Sheet1__2[[#This Row],[Probation (Months)]]) -> 44966
A19: 449 | B19: Risk Management | C19: Junior | D19: Analyst | E19: 44889 | F19: 44893 | G19: 44895 | H19: 44910 | I19: Yes | J19: 44910 | K19: Accepted | L19: 44912 | M19: Accepted | N19: 44911 | O19: 44920 | P19: 1 | Q19: 44923 | R19: 44926 | S19: 44941 | T19: C1030 | U19: Candidate_30 | V19: Job Board | W19: 6 | X19: 44903 | Y19: 7 | Z19: 2 | AA19: 6 | AB19: 15 | AC19: 3 | AD19: 1 | AE19: 4 | AF19: 18 | AG19: 15 | AH19: =EDATE(Sheet1__2[[#This Row],[Reporting date ]], Sheet1__2[[#This Row],[Probation (Months)]]) -> 45093
A20: 462 | B20: Risk Management | C20: Associate | D20: Analyst | E20: 44969 | F20: 44973 | G20: 44979 | H20: 44998 | I20: Yes | J20: 44996 | K20: Accepted | L20: 45001 | M20: Accepted | N20: 45000 | O20: 45004 | P20: 1 | Q20: 45005 | R20: 45010 | S20: 45028 | T20: C1032 | U20: Candidate_32 | V20: Referral | W20: 3 | X20: 44981 | Y20: 15 | Z20: 5 | AA20: 10 | AB20: 19 | AC20: 1 | AD20: 4 | AE20: 4 | AF20: 23 | AG20: 10 | AH20: =EDATE(Sheet1__2[[#This Row],[Reporting date ]], Sheet1__2[[#This Row],[Probation (Months)]]) -> 45092
A21: 470 | B21: Risk Management | C21: Executive | D21: Director | E21: 44975 | F21: 44978 | G21: 44979 | H21: 44999 | I21: Yes | J21: 44994 | K21: Decline | L21: 45000 | M21: Declined | N21: 44996 | P21: 0 | T21: C1037 | U21: Candidate_37 | V21: Referral | W21: 3 | X21: 44978 | Y21: 16 | Z21: 6 | AA21: 4 | AB21: 20 | AD21: 2 | AE21: 3 | AH21: =EDATE(Sheet1__2[[#This Row],[Reporting date ]], Sheet1__2[[#This Row],[Probation (Months)]]) -> 45088
A22: 496 | B22: Program Office | C22: Senior Management | D22: Senior Supervisory Manager | E22: 45167 | F22: 45170 | H22: 45180 | I22: Yes | J22: 45188 | K22: Decline | L22: 45196 | M22: Declined | N22: 45192 | P22: 0 | T22: C1068 | U22: Candidate_68 | V22: Referral | W22: 6 | X22: 45182 | Y22: 6 | Z22: 8 | AD22: 4 | AE22: 3 | AH22: =EDATE(Sheet1__2[[#This Row],[Reporting date ]], Sheet1__2[[#This Row],[Probation (Months)]]) -> 45374
A23: 486 | B23: Program Office | C23: Senior Management | D23: Senior Supervisory Manager | E23: 44936 | F23: 44937 | G23: 44938 | H23: 44944 | I23: Yes | J23: 44956 | K23: Decline | L23: 44960 | M23: Declined | N23: 44959 | P23: 0 | T23: C1069 | U23: Candidate_69 | V23: Linkedin | W23: 6 | X23: 44942 | Y23: 14 | Z23: 4 | AA23: 2 | AB23: 6 | AD23: 3 | AE23: 1 | AH23: =EDATE(Sheet1__2[[#This Row],[Reporting date ]], Sheet1__2[[#This Row],[Probation (Months)]]) -> 45140
A24: 481 | B24: Program Office | C24: Senior Management | D24: Senior Supervisory Manager | E24: 44930 | F24: 44934 | G24: 44938 | H24: 44951 | I24: Yes | J24: 44945 | K24: Accepted | L24: 44951 | M24: Accepted | N24: 44949 | O24: 44957 | P24: 1 | Q24: 44958 | R24: 44961 | S24: 44970 | T24: C1070 | U24: Candidate_70 | V24: Referral | W24: 6 | X24: 44933 | Y24: 12 | Z24: 6 | AA24: 8 | AB24: 13 | AC24: 1 | AD24: 4 | AE24: 4 | AF24: 12 | AG24: 12 | AH24: =EDATE(Sheet1__2[[#This Row],[Reporting date ]], Sheet1__2[[#This Row],[Probation (Months)]]) -> 45130
A25: 138 | B25: Program Office | C25: Senior Management | D25: Senior Supervisory Manager | E25: 44764 | F25: 44768 | G25: 44769 | H25: 44791 | I25: Yes | J25: 44774 | K25: Accepted | L25: 44778 | M25: Accepted | N25: 44775 | O25: 44777 | P25: 1 | Q25: 44778 | R25: 44782 | S25: 44801 | T25: C1078 | U25: Candidate_78 | V25: Referral | W25: 6 | X25: 44758 | Y25: 16 | Z25: 4 | AA25: 5 | AB25: 22 | AC25: 1 | AD25: 1 | AE25: 4 | AF25: 23 | AG25: 7 | AH25: =EDATE(Sheet1__2[[#This Row],[Reporting date ]], Sheet1__2[[#This Row],[Probation (Months)]]) -> 44959
A26: 2973 | B26: Program Office | C26: Senior | D26: Analyst | E26: 44757 | F26: 44761 | G26: 44769 | H26: 44776 | I26: Yes | J26: 44773 | K26: Accepted | L26: 44776 | M26: Accepted | N26: 44774 | O26: 44781 | P26: 1 | Q26: 44782 | R26: 44787 | S26: 44801 | T26: C1081 | U26: Candidate_81 | V26: Job Board | W26: 6 | X26: 44762 | Y26: 11 | Z26: 3 | AA26: 12 | AB26: 7 | AC26: 1 | AD26: 1 | AE26: 4 | AF26: 19 | AG26: 13 | AH26: =EDATE(Sheet1__2[[#This Row],[Reporting date ]], Sheet1__2[[#This Row],[Probation (Months)]]) -> 44958
A27: 2867 | B27: Program Office | C27: Senior | D27: Analyst | E27: 44849 | F27: 44853 | G27: 44860 | H27: 44930 | I27: Yes | J27: 44868 | K27: Accepted | L27: 44873 | M27: Accepted | N27: 44869 | O27: 44879 | P27: 1 | Q27: 44883 | R27: 44885 | S27: 44901 | T27: C1088 | U27: Candidate_88 | V27: Linkedin | W27: 6 | X27: 44855 | Y27: 13 | Z27: 5 | AA27: 11 | AB27: 70 | AC27: 4 | AD27: 1 | AE27: 4 | AF27: 18 | AG27: 16 | AH27: =EDATE(Sheet1__2[[#This Row],[Reporting date ]], Sheet1__2[[#This Row],[Probation (Months)]]) -> 45050
A28: 2851 | B28: Program Office | C28: Senior | D28: Analyst | E28: 45038 | F28: 45040 | G28: 45041 | H28: 45111 | I28: Yes | J28: 45056 | K28: Accepted | L28: 45058 | M28: Accepted | N28: 45057 | O28: 45067 | P28: 1 | Q28: 45071 | R28: 45073 | S28: 45091 | T28: C1092 | U28: Candidate_92 | V28: Linkedin | W28: 6 | X28: 45046 | Y28: 10 | Z28: 2 | AA28: 3 | AB28: 70 | AC28: 4 | AD28: 1 | AE28: 2 | AF28: 20 | AG28: 16 | AH28: =EDATE(Sheet1__2[[#This Row],[Reporting date ]], Sheet1__2[[#This Row],[Probation (Months)]]) -> 45241
A29: 2788 | B29: Program Office | C29: Senior | D29: Analyst | E29: 45104 | G29: 45110 | H29: 45126 | I29: Yes | J29: 45116 | K29: Decline | L29: 45123 | M29: Declined | N29: 45119 | P29: 0 | T29: C1095 | U29: Candidate_95 | V29: Linkedin | W29: 3 | X29: 45105 | Y29: 11 | Z29: 7 | AA29: 6 | AB29: 16 | AD29: 3 | AH29: =EDATE(Sheet1__2[[#This Row],[Reporting date ]], Sheet1__2[[#This Row],[Probation (Months)]]) -> 45211
A30: 2557 | B30: Program Office | C30: Senior | D30: Analyst | E30: 45144 | F30: 45145 | G30: 45148 | H30: 45167 | I30: Yes | J30: 45152 | K30: Accepted | L30: 45157 | M30: Accepted | N30: 45153 | O30: 45158 | P30: 1 | Q30: 45159 | R30: 45162 | S30: 45181 | T30: C1099 | U30: Candidate_99 | V30: Job Board | W30: 3 | X30: 45143 | Y30: 9 | Z30: 5 | AA30: 4 | AB30: 19 | AC30: 1 | AD30: 1 | AE30: 1 | AF30: 22 | AG30: 9 | AH30: =EDATE(Sheet1__2[[#This Row],[Reporting date ]], Sheet1__2[[#This Row],[Probation (Months)]]) -> 45245
A31: 2406 | B31: Program Office | C31: Senior | D31: Analyst | E31: 45014 | G31: 45022 | H31: 45048 | I31: Yes | J31: 45033 | K31: Decline | L31: 45037 | M31: Declined | N31: 45034 | P31: 0 | T31: C1102 | U31: Candidate_102 | V31: Linkedin | W31: 6 | X31: 45014 | Y31: 19 | Z31: 4 | AA31: 8 | AB31: 26 | AD31: 1 | AH31: =EDATE(Sheet1__2[[#This Row],[Reporting date ]], Sheet1__2[[#This Row],[Probation (Months)]]) -> 45217
A32: 2401 | B32: Program Office | C32: Senior | D32: Analyst | E32: 45016 | F32: 45019 | H32: 45050 | I32: Yes | J32: 45027 | K32: Decline | L32: 45034 | M32: Declined | N32: 45031 | P32: 0 | T32: C1103 | U32: Candidate_103 | V32: Linkedin | W32: 3 | X32: 45011 | Y32: 16 | Z32: 7 | AD32: 4 | AE32: 3 | AH32: =EDATE(Sheet1__2[[#This Row],[Reporting date ]], Sheet1__2[[#This Row],[Probation (Months)]]) -> 45122
A33: 2383 | B33: Program Office | C33: Senior | D33: Analyst | E33: 45031 | F33: 45034 | G33: 45036 | H33: 45055 | I33: Yes | J33: 45050 | K33: Accepted | L33: 45054 | M33: Accepted | N33: 45051 | O33: 45056 | P33: 1 | Q33: 45059 | R33: 45062 | S33: 45081 | T33: C1105 | U33: Candidate_105 | V33: Linkedin | W33: 3 | X33: 45034 | Y33: 16 | Z33: 4 | AA33: 5 | AB33: 19 | AC33: 3 | AD33: 1 | AE33: 3 | AF33: 22 | AG33: 11 | AH33: =EDATE(Sheet1__2[[#This Row],[Reporting date ]], Sheet1__2[[#This Row],[Probation (Months)]]) -> 45143
A34: 2313 | B34: Program Office | C34: Senior | D34: Analyst | E34: 44670 | F34: 44673 | G34: 44677 | H34: 44703 | I34: Yes | J34: 44688 | K34: Pending | L34: 44691 | M34: Pending | N34: 44689 | P34: 0 | T34: C1108 | U34: Candidate_108 | V34: Referral | W34: 3 | X34: 44678 | Y34: 10 | Z34: 3 | AA34: 7 | AB34: 26 | AD34: 1 | AE34: 3 | AH34: =EDATE(Sheet1__2[[#This Row],[Reporting date ]], Sheet1__2[[#This Row],[Probation (Months)]]) -> 44781
A35: 2263 | B35: Program Office | C35: Senior | D35: Analyst | E35: 45030 | G35: 45036 | H35: 45061 | I35: Yes | J35: 45053 | K35: Decline | L35: 45059 | M35: Declined | N35: 45056 | P35: 0 | T35: C1110 | U35: Candidate_110 | V35: Linkedin | W35: 3 | X35: 45040 | Y35: 13 | Z35: 6 | AA35: 6 | AB35: 25 | AD35: 3 | AH35: =EDATE(Sheet1__2[[#This Row],[Reporting date ]], Sheet1__2[[#This Row],[Probation (Months)]]) -> 45148
A36: 2200 | B36: Program Office | C36: Senior | D36: Analyst | E36: 44803 | G36: 44807 | H36: 44812 | I36: Yes | J36: 44822 | K36: Pending | L36: 44830 | M36: Pending | N36: 44826 | P36: 0 | T36: C1114 | U36: Candidate_114 | V36: Linkedin | W36: 3 | X36: 44805 | Y36: 17 | Z36: 8 | AA36: 4 | AB36: 5 | AD36: 4 | AH36: =EDATE(Sheet1__2[[#This Row],[Reporting date ]], Sheet1__2[[#This Row],[Probation (Months)]]) -> 44917
A37: 2197 | B37: Program Office | C37: Senior | D37: Analyst | E37: 44800 | F37: 44801 | G37: 44807 | H37: 44816 | I37: Yes | J37: 44822 | K37: Accepted | L37: 44827 | M37: Accepted | N37: 44826 | O37: 44828 | P37: 1 | Q37: 44829 | R37: 44835 | S37: 44854 | T37: C1115 | U37: Candidate_115 | V37: Referral | W37: 3 | X37: 44815 | Y37: 7 | Z37: 5 | AA37: 7 | AB37: 9 | AC37: 1 | AD37: 4 | AE37: 1 | AF37: 25 | AG37: 9 | AH37: =EDATE(Sheet1__2[[#This Row],[Reporting date ]], Sheet1__2[[#This Row],[Probation (Months)]]) -> 44917
A38: 2191 | B38: Program Office | C38: Senior | D38: Analyst | E38: 44800 | F38: 44803 | G38: 44807 | H38: 44821 | I38: Yes | J38: 44821 | K38: Pending | L38: 44825 | M38: Pending | N38: 44824 | P38: 0 | T38: C1116 | U38: Candidate_116 | V38: Referral | W38: 6 | X38: 44809 | Y38: 12 | Z38: 4 | AA38: 7 | AB38: 14 | AD38: 3 | AE38: 3 | AH38: =EDATE(Sheet1__2[[#This Row],[Reporting date ]], Sheet1__2[[#This Row],[Probation (Months)]]) -> 45005
A39: 2069 | B39: Program Office | C39: Senior | D39: Analyst | E39: 44867 | F39: 44869 | G39: 44873 | H39: 44903 | I39: Yes | J39: 44887 | K39: Accepted | L39: 44892 | M39: Accepted | N39: 44890 | O39: 44895 | P39: 1 | Q39: 44899 | R39: 44902 | S39: 44917 | T39: C1119 | U39: Candidate_119 | V39: Job Board | W39: 6 | X39: 44878 | Y39: 9 | Z39: 5 | AA39: 6 | AB39: 30 | AC39: 4 | AD39: 3 | AE39: 2 | AF39: 18 | AG39: 12 | AH39: =EDATE(Sheet1__2[[#This Row],[Reporting date ]], Sheet1__2[[#This Row],[Probation (Months)]]) -> 45071
A40: 2068 | B40: Program Office | C40: Senior | D40: Analyst | E40: 44870 | F40: 44872 | G40: 44873 | H40: 44902 | I40: Yes | J40: 44877 | K40: Accepted | L40: 44882 | M40: Accepted | N40: 44880 | O40: 44886 | P40: 1 | Q40: 44889 | R40: 44894 | S40: 44904 | T40: C1120 | U40: Candidate_120 | V40: Linkedin | W40: 6 | X40: 44872 | Y40: 5 | Z40: 5 | AA40: 3 | AB40: 29 | AC40: 3 | AD40: 3 | AE40: 2 | AF40: 15 | AG40: 14 | AH40: =EDATE(Sheet1__2[[#This Row],[Reporting date ]], Sheet1__2[[#This Row],[Probation (Months)]]) -> 45061
...

Sheet Dashboard

Sheet Bottlenecks or Delays in hiring
A1: STAGE OF RECRUITMENT | B1: AVERAGE DAYS
A2: Position Open Days | B2: =AVERAGE(Recruitment!AB4) -> 23
A3: Time to Close Employee File | B3: =AVERAGE(Recruitment!AF8) -> 20
A4: Time from Inclusion to Benefits | B4: =AVERAGE(Recruitment!AG8) -> 13
A5: Time from Application to Interview | B5: =AVERAGE(Sheet1__2[[#This Row],[Time between Application and Interview]]) -> 18
A6: Time to Publish Advert | B6: =AVERAGE(Recruitment!AA8) -> 9
A7: Days Taken Before Hiring | B7: =AVERAGE(Recruitment!Z8) -> 6
A8: Time to Approve Requisition | B8: =AVERAGE(Recruitment!AE8) -> 4
A9: Time Between Interview and Candidate Reporting | B9: =AVERAGE(Recruitment!AD8) -> 3
A10: Time Between File Opening and Onboarding | B10: =AVERAGE(Recruitment!AC8) -> 2
A12: HIGHEST DELAY IN HIRING IS THE DAYS A POSITION IS OPEN AND RECRUITMENT TEAM SHOULD FOCUS ON REDUCING THE DAYS A POSITION IS OPEN

Sheet Volume of Applications
A3: Row Labels | B3: Count of Candidate ID
A4: 2021 | B4: 1
A5: 2022 | B5: 220
A6: 2023 | B6: 142
A7: Grand Total | B7: 363

Sheet Candidate Source
A3: Row Labels | B3: Count of Candidate ID
A4: Job Board | B4: 273
A5: Linkedin | B5: 286
A6: Referral | B6: 253
A7: Grand Total | B7: 812

Sheet Dpt Hiring Performance
A3: Row Labels | B3: Sum of Hired
A4: Administation | B4: 11
A5: Capacity Building | B5: 63
A6: Communication and Advocacy | B6: 31
A7: Finance | B7: 85
A8: Fundraising | B8: 5
A9: HR | B9: 8
A10: IT | B10: 5
A11: M and E | B11: 42
A12: Operations | B12: 13
A13: Program Office | B13: 77
A14: Risk Management | B14: 6
A15: Grand Total | B15: 346

Sheet Applications Projection
A3: Count of Candidate ID | B3: Column Labels
A4: Row Labels | B4: 2022 | C4: Grand Total
A5: Jan | B5: 37 | C5: 37
A6: Feb | B6: 39 | C6: 39
A7: Mar | B7: 43 | C7: 43
A8: Apr | B8: 42 | C8: 42
A9: May | B9: 27 | C9: 27
A10: Jun | B10: 49 | C10: 49
A11: Jul | B11: 50 | C11: 50
A12: Aug | B12: 36 | C12: 36
A13: Sep | B13: 32 | C13: 32
A14: Oct | B14: 45 | C14: 45
A15: Nov | B15: 38 | C15: 38
A16: Dec | B16: 41 | C16: 41
A17: Grand Total | B17: 479 | C17: 479

Sheet Hiring Status
A3: Row Labels | B3: Count of Candidate ID
A4: Accepted | B4: 346
A5: Decline | B5: 363
A6: Pending | B6: 103
A7: Grand Total | B7: 812

Sheet Offer Status
A3: Row Labels | B3: Count of Candidate ID
A4: Accepted | B4: 346
A5: Declined | B5: 363
A6: Pending | B6: 103
A7: Grand Total | B7: 812
